Workbook

Sheet Summary
A1: Summary
A2: Pulls automatically from the Investments tab. To add another year, copy the last month's column formulas one column to the right and update the date header.
A4: Monthly Investment Gains by Account ($)
A5: Account | B5: 46023 | C5: 46054 | D5: 46082 | E5: 46113 | F5: 46143 | G5: 46174 | H5: 46204 | I5: 46235 | J5: 46266 | K5: 46296 | L5: 46327 | M5: 46357
A6: HSA 1 | B6: =SUMIFS(Investments!$F$17:$F$5000,Investments!$B$17:$B$5000,$A6,Investments!$A$17:$A$5000,B$5) -> 0 | C6: =SUMIFS(Investments!$F$17:$F$5000,Investments!$B$17:$B$5000,$A6,Investments!$A$17:$A$5000,C$5) -> 0 | D6: =SUMIFS(Investments!$F$17:$F$5000,Investments!$B$17:$B$5000,$A6,Investments!$A$17:$A$5000,D$5) -> 0 | E6: =SUMIFS(Investments!$F$17:$F$5000,Investments!$B$17:$B$5000,$A6,Investments!$A$17:$A$5000,E$5) -> 0 | F6: =SUMIFS(Investments!$F$17:$F$5000,Investments!$B$17:$B$5000,$A6,Investments!$A$17:$A$5000,F$5) -> 0 | G6: =SUMIFS(Investments!$F$17:$F$5000,Investments!$B$17:$B$5000,$A6,Investments!$A$17:$A$5000,G$5) -> 0 | H6: =SUMIFS(Investments!$F$17:$F$5000,Investments!$B$17:$B$5000,$A6,Investments!$A$17:$A$5000,H$5) -> 0 | I6: =SUMIFS(Investments!$F$17:$F$5000,Investments!$B$17:$B$5000,$A6,Investments!$A$17:$A$5000,I$5) -> 0 | ... M6: =SUMIFS(Investments!$F$17:$F$5000,Investments!$B$17:$B$5000,$A6,Investments!$A$17:$A$5000,M$5) -> 0
A7: HSA 2 | B7: =SUMIFS(Investments!$F$17:$F$5000,Investments!$B$17:$B$5000,$A7,Investments!$A$17:$A$5000,B$5) -> 0 | C7: =SUMIFS(Investments!$F$17:$F$5000,Investments!$B$17:$B$5000,$A7,Investments!$A$17:$A$5000,C$5) -> 0 | D7: =SUMIFS(Investments!$F$17:$F$5000,Investments!$B$17:$B$5000,$A7,Investments!$A$17:$A$5000,D$5) -> 0 | E7: =SUMIFS(Investments!$F$17:$F$5000,Investments!$B$17:$B$5000,$A7,Investments!$A$17:$A$5000,E$5) -> 0 | F7: =SUMIFS(Investments!$F$17:$F$5000,Investments!$B$17:$B$5000,$A7,Investments!$A$17:$A$5000,F$5) -> 0 | G7: =SUMIFS(Investments!$F$17:$F$5000,Investments!$B$17:$B$5000,$A7,Investments!$A$17:$A$5000,G$5) -> 0 | H7: =SUMIFS(Investments!$F$17:$F$5000,Investments!$B$17:$B$5000,$A7,Investments!$A$17:$A$5000,H$5) -> 0 | I7: =SUMIFS(Investments!$F$17:$F$5000,Investments!$B$17:$B$5000,$A7,Investments!$A$17:$A$5000,I$5) -> 0 | ... M7: =SUMIFS(Investments!$F$17:$F$5000,Investments!$B$17:$B$5000,$A7,Investments!$A$17:$A$5000,M$5) -> 0
A8: Roth IRA | B8: =SUMIFS(Investments!$F$17:$F$5000,Investments!$B$17:$B$5000,$A8,Investments!$A$17:$A$5000,B$5) -> 0 | C8: =SUMIFS(Investments!$F$17:$F$5000,Investments!$B$17:$B$5000,$A8,Investments!$A$17:$A$5000,C$5) -> 0 | D8: =SUMIFS(Investments!$F$17:$F$5000,Investments!$B$17:$B$5000,$A8,Investments!$A$17:$A$5000,D$5) -> 0 | E8: =SUMIFS(Investments!$F$17:$F$5000,Investments!$B$17:$B$5000,$A8,Investments!$A$17:$A$5000,E$5) -> 0 | F8: =SUMIFS(Investments!$F$17:$F$5000,Investments!$B$17:$B$5000,$A8,Investments!$A$17:$A$5000,F$5) -> 0 | G8: =SUMIFS(Investments!$F$17:$F$5000,Investments!$B$17:$B$5000,$A8,Investments!$A$17:$A$5000,G$5) -> 0 | H8: =SUMIFS(Investments!$F$17:$F$5000,Investments!$B$17:$B$5000,$A8,Investments!$A$17:$A$5000,H$5) -> 0 | I8: =SUMIFS(Investments!$F$17:$F$5000,Investments!$B$17:$B$5000,$A8,Investments!$A$17:$A$5000,I$5) -> 0 | ... M8: =SUMIFS(Investments!$F$17:$F$5000,Investments!$B$17:$B$5000,$A8,Investments!$A$17:$A$5000,M$5) -> 0
A9: 401k 1 | B9: =SUMIFS(Investments!$F$17:$F$5000,Investments!$B$17:$B$5000,$A9,Investments!$A$17:$A$5000,B$5) -> 0 | C9: =SUMIFS(Investments!$F$17:$F$5000,Investments!$B$17:$B$5000,$A9,Investments!$A$17:$A$5000,C$5) -> 0 | D9: =SUMIFS(Investments!$F$17:$F$5000,Investments!$B$17:$B$5000,$A9,Investments!$A$17:$A$5000,D$5) -> 0 | E9: =SUMIFS(Investments!$F$17:$F$5000,Investments!$B$17:$B$5000,$A9,Investments!$A$17:$A$5000,E$5) -> 0 | F9: =SUMIFS(Investments!$F$17:$F$5000,Investments!$B$17:$B$5000,$A9,Investments!$A$17:$A$5000,F$5) -> 0 | G9: =SUMIFS(Investments!$F$17:$F$5000,Investments!$B$17:$B$5000,$A9,Investments!$A$17:$A$5000,G$5) -> 0 | H9: =SUMIFS(Investments!$F$17:$F$5000,Investments!$B$17:$B$5000,$A9,Investments!$A$17:$A$5000,H$5) -> 0 | I9: =SUMIFS(Investments!$F$17:$F$5000,Investments!$B$17:$B$5000,$A9,Investments!$A$17:$A$5000,I$5) -> 0 | ... M9: =SUMIFS(Investments!$F$17:$F$5000,Investments!$B$17:$B$5000,$A9,Investments!$A$17:$A$5000,M$5) -> 0
A10: 401k 2 | B10: =SUMIFS(Investments!$F$17:$F$5000,Investments!$B$17:$B$5000,$A10,Investments!$A$17:$A$5000,B$5) -> 0 | C10: =SUMIFS(Investments!$F$17:$F$5000,Investments!$B$17:$B$5000,$A10,Investments!$A$17:$A$5000,C$5) -> 0 | D10: =SUMIFS(Investments!$F$17:$F$5000,Investments!$B$17:$B$5000,$A10,Investments!$A$17:$A$5000,D$5) -> 0 | E10: =SUMIFS(Investments!$F$17:$F$5000,Investments!$B$17:$B$5000,$A10,Investments!$A$17:$A$5000,E$5) -> 0 | F10: =SUMIFS(Investments!$F$17:$F$5000,Investments!$B$17:$B$5000,$A10,Investments!$A$17:$A$5000,F$5) -> 0 | G10: =SUMIFS(Investments!$F$17:$F$5000,Investments!$B$17:$B$5000,$A10,Investments!$A$17:$A$5000,G$5) -> 0 | H10: =SUMIFS(Investments!$F$17:$F$5000,Investments!$B$17:$B$5000,$A10,Investments!$A$17:$A$5000,H$5) -> 0 | I10: =SUMIFS(Investments!$F$17:$F$5000,Investments!$B$17:$B$5000,$A10,Investments!$A$17:$A$5000,I$5) -> 0 | ... M10: =SUMIFS(Investments!$F$17:$F$5000,Investments!$B$17:$B$5000,$A10,Investments!$A$17:$A$5000,M$5) -> 0
A11: HYSA | B11: =SUMIFS(Investments!$F$17:$F$5000,Investments!$B$17:$B$5000,$A11,Investments!$A$17:$A$5000,B$5) -> 0 | C11: =SUMIFS(Investments!$F$17:$F$5000,Investments!$B$17:$B$5000,$A11,Investments!$A$17:$A$5000,C$5) -> 0 | D11: =SUMIFS(Investments!$F$17:$F$5000,Investments!$B$17:$B$5000,$A11,Investments!$A$17:$A$5000,D$5) -> 0 | E11: =SUMIFS(Investments!$F$17:$F$5000,Investments!$B$17:$B$5000,$A11,Investments!$A$17:$A$5000,E$5) -> 0 | F11: =SUMIFS(Investments!$F$17:$F$5000,Investments!$B$17:$B$5000,$A11,Investments!$A$17:$A$5000,F$5) -> 0 | G11: =SUMIFS(Investments!$F$17:$F$5000,Investments!$B$17:$B$5000,$A11,Investments!$A$17:$A$5000,G$5) -> 0 | H11: =SUMIFS(Investments!$F$17:$F$5000,Investments!$B$17:$B$5000,$A11,Investments!$A$17:$A$5000,H$5) -> 0 | I11: =SUMIFS(Investments!$F$17:$F$5000,Investments!$B$17:$B$5000,$A11,Investments!$A$17:$A$5000,I$5) -> 0 | ... M11: =SUMIFS(Investments!$F$17:$F$5000,Investments!$B$17:$B$5000,$A11,Investments!$A$17:$A$5000,M$5) -> 0
A12: Checking 1 | B12: =SUMIFS(Investments!$F$17:$F$5000,Investments!$B$17:$B$5000,$A12,Investments!$A$17:$A$5000,B$5) -> 0 | C12: =SUMIFS(Investments!$F$17:$F$5000,Investments!$B$17:$B$5000,$A12,Investments!$A$17:$A$5000,C$5) -> 0 | D12: =SUMIFS(Investments!$F$17:$F$5000,Investments!$B$17:$B$5000,$A12,Investments!$A$17:$A$5000,D$5) -> 0 | E12: =SUMIFS(Investments!$F$17:$F$5000,Investments!$B$17:$B$5000,$A12,Investments!$A$17:$A$5000,E$5) -> 0 | F12: =SUMIFS(Investments!$F$17:$F$5000,Investments!$B$17:$B$5000,$A12,Investments!$A$17:$A$5000,F$5) -> 0 | G12: =SUMIFS(Investments!$F$17:$F$5000,Investments!$B$17:$B$5000,$A12,Investments!$A$17:$A$5000,G$5) -> 0 | H12: =SUMIFS(Investments!$F$17:$F$5000,Investments!$B$17:$B$5000,$A12,Investments!$A$17:$A$5000,H$5) -> 0 | I12: =SUMIFS(Investments!$F$17:$F$5000,Investments!$B$17:$B$5000,$A12,Investments!$A$17:$A$5000,I$5) -> 0 | ... M12: =SUMIFS(Investments!$F$17:$F$5000,Investments!$B$17:$B$5000,$A12,Investments!$A$17:$A$5000,M$5) -> 0
A13: Checking 2 | B13: =SUMIFS(Investments!$F$17:$F$5000,Investments!$B$17:$B$5000,$A13,Investments!$A$17:$A$5000,B$5) -> 0 | C13: =SUMIFS(Investments!$F$17:$F$5000,Investments!$B$17:$B$5000,$A13,Investments!$A$17:$A$5000,C$5) -> 0 | D13: =SUMIFS(Investments!$F$17:$F$5000,Investments!$B$17:$B$5000,$A13,Investments!$A$17:$A$5000,D$5) -> 0 | E13: =SUMIFS(Investments!$F$17:$F$5000,Investments!$B$17:$B$5000,$A13,Investments!$A$17:$A$5000,E$5) -> 0 | F13: =SUMIFS(Investments!$F$17:$F$5000,Investments!$B$17:$B$5000,$A13,Investments!$A$17:$A$5000,F$5) -> 0 | G13: =SUMIFS(Investments!$F$17:$F$5000,Investments!$B$17:$B$5000,$A13,Investments!$A$17:$A$5000,G$5) -> 0 | H13: =SUMIFS(Investments!$F$17:$F$5000,Investments!$B$17:$B$5000,$A13,Investments!$A$17:$A$5000,H$5) -> 0 | I13: =SUMIFS(Investments!$F$17:$F$5000,Investments!$B$17:$B$5000,$A13,Investments!$A$17:$A$5000,I$5) -> 0 | ... M13: =SUMIFS(Investments!$F$17:$F$5000,Investments!$B$17:$B$5000,$A13,Investments!$A$17:$A$5000,M$5) -> 0
A14: Total Gains | B14: =SUM(B6:B13) -> 0 | C14: =SUM(C6:C13) -> 0 | D14: =SUM(D6:D13) -> 0 | E14: =SUM(E6:E13) -> 0 | F14: =SUM(F6:F13) -> 0 | G14: =SUM(G6:G13) -> 0 | H14: =SUM(H6:H13) -> 0 | I14: =SUM(I6:I13) -> 0 | ... M14: =SUM(M6:M13) -> 0
A17: Account Balance by Month ($)
A18: Account | B18: 46023 | C18: 46054 | D18: 46082 | E18: 46113 | F18: 46143 | G18: 46174 | H18: 46204 | I18: 46235 | J18: 46266 | K18: 46296 | L18: 46327 | M18: 46357
A19: HSA 1 | B19: =SUMIFS(Investments!$C$17:$C$5000,Investments!$B$17:$B$5000,$A19,Investments!$A$17:$A$5000,B$18) -> 0 | C19: =SUMIFS(Investments!$C$17:$C$5000,Investments!$B$17:$B$5000,$A19,Investments!$A$17:$A$5000,C$18) -> 0 | D19: =SUMIFS(Investments!$C$17:$C$5000,Investments!$B$17:$B$5000,$A19,Investments!$A$17:$A$5000,D$18) -> 0 | E19: =SUMIFS(Investments!$C$17:$C$5000,Investments!$B$17:$B$5000,$A19,Investments!$A$17:$A$5000,E$18) -> 0 | F19: =SUMIFS(Investments!$C$17:$C$5000,Investments!$B$17:$B$5000,$A19,Investments!$A$17:$A$5000,F$18) -> 0 | G19: =SUMIFS(Investments!$C$17:$C$5000,Investments!$B$17:$B$5000,$A19,Investments!$A$17:$A$5000,G$18) -> 0 | H19: =SUMIFS(Investments!$C$17:$C$5000,Investments!$B$17:$B$5000,$A19,Investments!$A$17:$A$5000,H$18) -> 0 | I19: =SUMIFS(Investments!$C$17:$C$5000,Investments!$B$17:$B$5000,$A19,Investments!$A$17:$A$5000,I$18) -> 0 | ... M19: =SUMIFS(Investments!$C$17:$C$5000,Investments!$B$17:$B$5000,$A19,Investments!$A$17:$A$5000,M$18) -> 0
A20: HSA 2 | B20: =SUMIFS(Investments!$C$17:$C$5000,Investments!$B$17:$B$5000,$A20,Investments!$A$17:$A$5000,B$18) -> 0 | C20: =SUMIFS(Investments!$C$17:$C$5000,Investments!$B$17:$B$5000,$A20,Investments!$A$17:$A$5000,C$18) -> 0 | D20: =SUMIFS(Investments!$C$17:$C$5000,Investments!$B$17:$B$5000,$A20,Investments!$A$17:$A$5000,D$18) -> 0 | E20: =SUMIFS(Investments!$C$17:$C$5000,Investments!$B$17:$B$5000,$A20,Investments!$A$17:$A$5000,E$18) -> 0 | F20: =SUMIFS(Investments!$C$17:$C$5000,Investments!$B$17:$B$5000,$A20,Investments!$A$17:$A$5000,F$18) -> 0 | G20: =SUMIFS(Investments!$C$17:$C$5000,Investments!$B$17:$B$5000,$A20,Investments!$A$17:$A$5000,G$18) -> 0 | H20: =SUMIFS(Investments!$C$17:$C$5000,Investments!$B$17:$B$5000,$A20,Investments!$A$17:$A$5000,H$18) -> 0 | I20: =SUMIFS(Investments!$C$17:$C$5000,Investments!$B$17:$B$5000,$A20,Investments!$A$17:$A$5000,I$18) -> 0 | ... M20: =SUMIFS(Investments!$C$17:$C$5000,Investments!$B$17:$B$5000,$A20,Investments!$A$17:$A$5000,M$18) -> 0
A21: Roth IRA | B21: =SUMIFS(Investments!$C$17:$C$5000,Investments!$B$17:$B$5000,$A21,Investments!$A$17:$A$5000,B$18) -> 0 | C21: =SUMIFS(Investments!$C$17:$C$5000,Investments!$B$17:$B$5000,$A21,Investments!$A$17:$A$5000,C$18) -> 0 | D21: =SUMIFS(Investments!$C$17:$C$5000,Investments!$B$17:$B$5000,$A21,Investments!$A$17:$A$5000,D$18) -> 0 | E21: =SUMIFS(Investments!$C$17:$C$5000,Investments!$B$17:$B$5000,$A21,Investments!$A$17:$A$5000,E$18) -> 0 | F21: =SUMIFS(Investments!$C$17:$C$5000,Investments!$B$17:$B$5000,$A21,Investments!$A$17:$A$5000,F$18) -> 0 | G21: =SUMIFS(Investments!$C$17:$C$5000,Investments!$B$17:$B$5000,$A21,Investments!$A$17:$A$5000,G$18) -> 0 | H21: =SUMIFS(Investments!$C$17:$C$5000,Investments!$B$17:$B$5000,$A21,Investments!$A$17:$A$5000,H$18) -> 0 | I21: =SUMIFS(Investments!$C$17:$C$5000,Investments!$B$17:$B$5000,$A21,Investments!$A$17:$A$5000,I$18) -> 0 | ... M21: =SUMIFS(Investments!$C$17:$C$5000,Investments!$B$17:$B$5000,$A21,Investments!$A$17:$A$5000,M$18) -> 0
A22: 401k 1 | B22: =SUMIFS(Investments!$C$17:$C$5000,Investments!$B$17:$B$5000,$A22,Investments!$A$17:$A$5000,B$18) -> 0 | C22: =SUMIFS(Investments!$C$17:$C$5000,Investments!$B$17:$B$5000,$A22,Investments!$A$17:$A$5000,C$18) -> 0 | D22: =SUMIFS(Investments!$C$17:$C$5000,Investments!$B$17:$B$5000,$A22,Investments!$A$17:$A$5000,D$18) -> 0 | E22: =SUMIFS(Investments!$C$17:$C$5000,Investments!$B$17:$B$5000,$A22,Investments!$A$17:$A$5000,E$18) -> 0 | F22: =SUMIFS(Investments!$C$17:$C$5000,Investments!$B$17:$B$5000,$A22,Investments!$A$17:$A$5000,F$18) -> 0 | G22: =SUMIFS(Investments!$C$17:$C$5000,Investments!$B$17:$B$5000,$A22,Investments!$A$17:$A$5000,G$18) -> 0 | H22: =SUMIFS(Investments!$C$17:$C$5000,Investments!$B$17:$B$5000,$A22,Investments!$A$17:$A$5000,H$18) -> 0 | I22: =SUMIFS(Investments!$C$17:$C$5000,Investments!$B$17:$B$5000,$A22,Investments!$A$17:$A$5000,I$18) -> 0 | ... M22: =SUMIFS(Investments!$C$17:$C$5000,Investments!$B$17:$B$5000,$A22,Investments!$A$17:$A$5000,M$18) -> 0
A23: 401k 2 | B23: =SUMIFS(Investments!$C$17:$C$5000,Investments!$B$17:$B$5000,$A23,Investments!$A$17:$A$5000,B$18) -> 0 | C23: =SUMIFS(Investments!$C$17:$C$5000,Investments!$B$17:$B$5000,$A23,Investments!$A$17:$A$5000,C$18) -> 0 | D23: =SUMIFS(Investments!$C$17:$C$5000,Investments!$B$17:$B$5000,$A23,Investments!$A$17:$A$5000,D$18) -> 0 | E23: =SUMIFS(Investments!$C$17:$C$5000,Investments!$B$17:$B$5000,$A23,Investments!$A$17:$A$5000,E$18) -> 0 | F23: =SUMIFS(Investments!$C$17:$C$5000,Investments!$B$17:$B$5000,$A23,Investments!$A$17:$A$5000,F$18) -> 0 | G23: =SUMIFS(Investments!$C$17:$C$5000,Investments!$B$17:$B$5000,$A23,Investments!$A$17:$A$5000,G$18) -> 0 | H23: =SUMIFS(Investments!$C$17:$C$5000,Investments!$B$17:$B$5000,$A23,Investments!$A$17:$A$5000,H$18) -> 0 | I23: =SUMIFS(Investments!$C$17:$C$5000,Investments!$B$17:$B$5000,$A23,Investments!$A$17:$A$5000,I$18) -> 0 | ... M23: =SUMIFS(Investments!$C$17:$C$5000,Investments!$B$17:$B$5000,$A23,Investments!$A$17:$A$5000,M$18) -> 0
A24: HYSA | B24: =SUMIFS(Investments!$C$17:$C$5000,Investments!$B$17:$B$5000,$A24,Investments!$A$17:$A$5000,B$18) -> 0 | C24: =SUMIFS(Investments!$C$17:$C$5000,Investments!$B$17:$B$5000,$A24,Investments!$A$17:$A$5000,C$18) -> 0 | D24: =SUMIFS(Investments!$C$17:$C$5000,Investments!$B$17:$B$5000,$A24,Investments!$A$17:$A$5000,D$18) -> 0 | E24: =SUMIFS(Investments!$C$17:$C$5000,Investments!$B$17:$B$5000,$A24,Investments!$A$17:$A$5000,E$18) -> 0 | F24: =SUMIFS(Investments!$C$17:$C$5000,Investments!$B$17:$B$5000,$A24,Investments!$A$17:$A$5000,F$18) -> 0 | G24: =SUMIFS(Investments!$C$17:$C$5000,Investments!$B$17:$B$5000,$A24,Investments!$A$17:$A$5000,G$18) -> 0 | H24: =SUMIFS(Investments!$C$17:$C$5000,Investments!$B$17:$B$5000,$A24,Investments!$A$17:$A$5000,H$18) -> 0 | I24: =SUMIFS(Investments!$C$17:$C$5000,Investments!$B$17:$B$5000,$A24,Investments!$A$17:$A$5000,I$18) -> 0 | ... M24: =SUMIFS(Investments!$C$17:$C$5000,Investments!$B$17:$B$5000,$A24,Investments!$A$17:$A$5000,M$18) -> 0
A25: Checking 1 | B25: =SUMIFS(Investments!$C$17:$C$5000,Investments!$B$17:$B$5000,$A25,Investments!$A$17:$A$5000,B$18) -> 0 | C25: =SUMIFS(Investments!$C$17:$C$5000,Investments!$B$17:$B$5000,$A25,Investments!$A$17:$A$5000,C$18) -> 0 | D25: =SUMIFS(Investments!$C$17:$C$5000,Investments!$B$17:$B$5000,$A25,Investments!$A$17:$A$5000,D$18) -> 0 | E25: =SUMIFS(Investments!$C$17:$C$5000,Investments!$B$17:$B$5000,$A25,Investments!$A$17:$A$5000,E$18) -> 0 | F25: =SUMIFS(Investments!$C$17:$C$5000,Investments!$B$17:$B$5000,$A25,Investments!$A$17:$A$5000,F$18) -> 0 | G25: =SUMIFS(Investments!$C$17:$C$5000,Investments!$B$17:$B$5000,$A25,Investments!$A$17:$A$5000,G$18) -> 0 | H25: =SUMIFS(Investments!$C$17:$C$5000,Investments!$B$17:$B$5000,$A25,Investments!$A$17:$A$5000,H$18) -> 0 | I25: =SUMIFS(Investments!$C$17:$C$5000,Investments!$B$17:$B$5000,$A25,Investments!$A$17:$A$5000,I$18) -> 0 | ... M25: =SUMIFS(Investments!$C$17:$C$5000,Investments!$B$17:$B$5000,$A25,Investments!$A$17:$A$5000,M$18) -> 0
A26: Checking 2 | B26: =SUMIFS(Investments!$C$17:$C$5000,Investments!$B$17:$B$5000,$A26,Investments!$A$17:$A$5000,B$18) -> 0 | C26: =SUMIFS(Investments!$C$17:$C$5000,Investments!$B$17:$B$5000,$A26,Investments!$A$17:$A$5000,C$18) -> 0 | D26: =SUMIFS(Investments!$C$17:$C$5000,Investments!$B$17:$B$5000,$A26,Investments!$A$17:$A$5000,D$18) -> 0 | E26: =SUMIFS(Investments!$C$17:$C$5000,Investments!$B$17:$B$5000,$A26,Investments!$A$17:$A$5000,E$18) -> 0 | F26: =SUMIFS(Investments!$C$17:$C$5000,Investments!$B$17:$B$5000,$A26,Investments!$A$17:$A$5000,F$18) -> 0 | G26: =SUMIFS(Investments!$C$17:$C$5000,Investments!$B$17:$B$5000,$A26,Investments!$A$17:$A$5000,G$18) -> 0 | H26: =SUMIFS(Investments!$C$17:$C$5000,Investments!$B$17:$B$5000,$A26,Investments!$A$17:$A$5000,H$18) -> 0 | I26: =SUMIFS(Investments!$C$17:$C$5000,Investments!$B$17:$B$5000,$A26,Investments!$A$17:$A$5000,I$18) -> 0 | ... M26: =SUMIFS(Investments!$C$17:$C$5000,Investments!$B$17:$B$5000,$A26,Investments!$A$17:$A$5000,M$18) -> 0
A27: Net Worth | B27: =SUM(B19:B26) -> 0 | C27: =SUM(C19:C26) -> 0 | D27: =SUM(D19:D26) -> 0 | E27: =SUM(E19:E26) -> 0 | F27: =SUM(F19:F26) -> 0 | G27: =SUM(G19:G26) -> 0 | H27: =SUM(H19:H26) -> 0 | I27: =SUM(I19:I26) -> 0 | ... M27: =SUM(M19:M26) -> 0
A66: Monthly Spending by Category ($)
A67: Category | B67: 46023 | C67: 46054 | D67: 46082 | E67: 46113 | F67: 46143 | G67: 46174 | H67: 46204 | I67: 46235 | J67: 46266 | K67: 46296 | L67: 46327 | M67: 46357
A68: Housing | B68: =SUMIFS(Expenses!$C$5:$C$504,Expenses!$D$5:$D$504,$A68,Expenses!$A$5:$A$504,">="&B$67,Expenses!$A$5:$A$504,"<"&EDATE(B$67,1)) -> 0 | C68: =SUMIFS(Expenses!$C$5:$C$504,Expenses!$D$5:$D$504,$A68,Expenses!$A$5:$A$504,">="&C$67,Expenses!$A$5:$A$504,"<"&EDATE(C$67,1)) -> 0 | D68: =SUMIFS(Expenses!$C$5:$C$504,Expenses!$D$5:$D$504,$A68,Expenses!$A$5:$A$504,">="&D$67,Expenses!$A$5:$A$504,"<"&EDATE(D$67,1)) -> 0 | E68: =SUMIFS(Expenses!$C$5:$C$504,Expenses!$D$5:$D$504,$A68,Expenses!$A$5:$A$504,">="&E$67,Expenses!$A$5:$A$504,"<"&EDATE(E$67,1)) -> 0 | F68: =SUMIFS(Expenses!$C$5:$C$504,Expenses!$D$5:$D$504,$A68,Expenses!$A$5:$A$504,">="&F$67,Expenses!$A$5:$A$504,"<"&EDATE(F$67,1)) -> 0 | G68: =SUMIFS(Expenses!$C$5:$C$504,Expenses!$D$5:$D$504,$A68,Expenses!$A$5:$A$504,">="&G$67,Expenses!$A$5:$A$504,"<"&EDATE(G$67,1)) -> 0 | H68: =SUMIFS(Expenses!$C$5:$C$504,Expenses!$D$5:$D$504,$A68,Expenses!$A$5:$A$504,">="&H$67,Expenses!$A$5:$A$504,"<"&EDATE(H$67,1)) -> 0 | I68: =SUMIFS(Expenses!$C$5:$C$504,Expenses!$D$5:$D$504,$A68,Expenses!$A$5:$A$504,">="&I$67,Expenses!$A$5:$A$504,"<"&EDATE(I$67,1)) -> 0 | ... M68: =SUMIFS(Expenses!$C$5:$C$504,Expenses!$D$5:$D$504,$A68,Expenses!$A$5:$A$504,">="&M$67,Expenses!$A$5:$A$504,"<"&EDATE(M$67,1)) -> 0
A69: Groceries | B69: =SUMIFS(Expenses!$C$5:$C$504,Expenses!$D$5:$D$504,$A69,Expenses!$A$5:$A$504,">="&B$67,Expenses!$A$5:$A$504,"<"&EDATE(B$67,1)) -> 85.32 | C69: =SUMIFS(Expenses!$C$5:$C$504,Expenses!$D$5:$D$504,$A69,Expenses!$A$5:$A$504,">="&C$67,Expenses!$A$5:$A$504,"<"&EDATE(C$67,1)) -> 0 | D69: =SUMIFS(Expenses!$C$5:$C$504,Expenses!$D$5:$D$504,$A69,Expenses!$A$5:$A$504,">="&D$67,Expenses!$A$5:$A$504,"<"&EDATE(D$67,1)) -> 0 | E69: =SUMIFS(Expenses!$C$5:$C$504,Expenses!$D$5:$D$504,$A69,Expenses!$A$5:$A$504,">="&E$67,Expenses!$A$5:$A$504,"<"&EDATE(E$67,1)) -> 0 | F69: =SUMIFS(Expenses!$C$5:$C$504,Expenses!$D$5:$D$504,$A69,Expenses!$A$5:$A$504,">="&F$67,Expenses!$A$5:$A$504,"<"&EDATE(F$67,1)) -> 0 | G69: =SUMIFS(Expenses!$C$5:$C$504,Expenses!$D$5:$D$504,$A69,Expenses!$A$5:$A$504,">="&G$67,Expenses!$A$5:$A$504,"<"&EDATE(G$67,1)) -> 0 | H69: =SUMIFS(Expenses!$C$5:$C$504,Expenses!$D$5:$D$504,$A69,Expenses!$A$5:$A$504,">="&H$67,Expenses!$A$5:$A$504,"<"&EDATE(H$67,1)) -> 0 | I69: =SUMIFS(Expenses!$C$5:$C$504,Expenses!$D$5:$D$504,$A69,Expenses!$A$5:$A$504,">="&I$67,Expenses!$A$5:$A$504,"<"&EDATE(I$67,1)) -> 0 | ... M69: =SUMIFS(Expenses!$C$5:$C$504,Expenses!$D$5:$D$504,$A69,Expenses!$A$5:$A$504,">="&M$67,Expenses!$A$5:$A$504,"<"&EDATE(M$67,1)) -> 0
A70: Dining | B70: =SUMIFS(Expenses!$C$5:$C$504,Expenses!$D$5:$D$504,$A70,Expenses!$A$5:$A$504,">="&B$67,Expenses!$A$5:$A$504,"<"&EDATE(B$67,1)) -> 0 | C70: =SUMIFS(Expenses!$C$5:$C$504,Expenses!$D$5:$D$504,$A70,Expenses!$A$5:$A$504,">="&C$67,Expenses!$A$5:$A$504,"<"&EDATE(C$67,1)) -> 0 | D70: =SUMIFS(Expenses!$C$5:$C$504,Expenses!$D$5:$D$504,$A70,Expenses!$A$5:$A$504,">="&D$67,Expenses!$A$5:$A$504,"<"&EDATE(D$67,1)) -> 0 | E70: =SUMIFS(Expenses!$C$5:$C$504,Expenses!$D$5:$D$504,$A70,Expenses!$A$5:$A$504,">="&E$67,Expenses!$A$5:$A$504,"<"&EDATE(E$67,1)) -> 0 | F70: =SUMIFS(Expenses!$C$5:$C$504,Expenses!$D$5:$D$504,$A70,Expenses!$A$5:$A$504,">="&F$67,Expenses!$A$5:$A$504,"<"&EDATE(F$67,1)) -> 0 | G70: =SUMIFS(Expenses!$C$5:$C$504,Expenses!$D$5:$D$504,$A70,Expenses!$A$5:$A$504,">="&G$67,Expenses!$A$5:$A$504,"<"&EDATE(G$67,1)) -> 0 | H70: =SUMIFS(Expenses!$C$5:$C$504,Expenses!$D$5:$D$504,$A70,Expenses!$A$5:$A$504,">="&H$67,Expenses!$A$5:$A$504,"<"&EDATE(H$67,1)) -> 0 | I70: =SUMIFS(Expenses!$C$5:$C$504,Expenses!$D$5:$D$504,$A70,Expenses!$A$5:$A$504,">="&I$67,Expenses!$A$5:$A$504,"<"&EDATE(I$67,1)) -> 0 | ... M70: =SUMIFS(Expenses!$C$5:$C$504,Expenses!$D$5:$D$504,$A70,Expenses!$A$5:$A$504,">="&M$67,Expenses!$A$5:$A$504,"<"&EDATE(M$67,1)) -> 0
A71: Transportation | B71: =SUMIFS(Expenses!$C$5:$C$504,Expenses!$D$5:$D$504,$A71,Expenses!$A$5:$A$504,">="&B$67,Expenses!$A$5:$A$504,"<"&EDATE(B$67,1)) -> 0 | C71: =SUMIFS(Expenses!$C$5:$C$504,Expenses!$D$5:$D$504,$A71,Expenses!$A$5:$A$504,">="&C$67,Expenses!$A$5:$A$504,"<"&EDATE(C$67,1)) -> 0 | D71: =SUMIFS(Expenses!$C$5:$C$504,Expenses!$D$5:$D$504,$A71,Expenses!$A$5:$A$504,">="&D$67,Expenses!$A$5:$A$504,"<"&EDATE(D$67,1)) -> 0 | E71: =SUMIFS(Expenses!$C$5:$C$504,Expenses!$D$5:$D$504,$A71,Expenses!$A$5:$A$504,">="&E$67,Expenses!$A$5:$A$504,"<"&EDATE(E$67,1)) -> 0 | F71: =SUMIFS(Expenses!$C$5:$C$504,Expenses!$D$5:$D$504,$A71,Expenses!$A$5:$A$504,">="&F$67,Expenses!$A$5:$A$504,"<"&EDATE(F$67,1)) -> 0 | G71: =SUMIFS(Expenses!$C$5:$C$504,Expenses!$D$5:$D$504,$A71,Expenses!$A$5:$A$504,">="&G$67,Expenses!$A$5:$A$504,"<"&EDATE(G$67,1)) -> 0 | H71: =SUMIFS(Expenses!$C$5:$C$504,Expenses!$D$5:$D$504,$A71,Expenses!$A$5:$A$504,">="&H$67,Expenses!$A$5:$A$504,"<"&EDATE(H$67,1)) -> 0 | I71: =SUMIFS(Expenses!$C$5:$C$504,Expenses!$D$5:$D$504,$A71,Expenses!$A$5:$A$504,">="&I$67,Expenses!$A$5:$A$504,"<"&EDATE(I$67,1)) -> 0 | ... M71: =SUMIFS(Expenses!$C$5:$C$504,Expenses!$D$5:$D$504,$A71,Expenses!$A$5:$A$504,">="&M$67,Expenses!$A$5:$A$504,"<"&EDATE(M$67,1)) -> 0
A72: Utilities | B72: =SUMIFS(Expenses!$C$5:$C$504,Expenses!$D$5:$D$504,$A72,Expenses!$A$5:$A$504,">="&B$67,Expenses!$A$5:$A$504,"<"&EDATE(B$67,1)) -> 0 | C72: =SUMIFS(Expenses!$C$5:$C$504,Expenses!$D$5:$D$504,$A72,Expenses!$A$5:$A$504,">="&C$67,Expenses!$A$5:$A$504,"<"&EDATE(C$67,1)) -> 0 | D72: =SUMIFS(Expenses!$C$5:$C$504,Expenses!$D$5:$D$504,$A72,Expenses!$A$5:$A$504,">="&D$67,Expenses!$A$5:$A$504,"<"&EDATE(D$67,1)) -> 0 | E72: =SUMIFS(Expenses!$C$5:$C$504,Expenses!$D$5:$D$504,$A72,Expenses!$A$5:$A$504,">="&E$67,Expenses!$A$5:$A$504,"<"&EDATE(E$67,1)) -> 0 | F72: =SUMIFS(Expenses!$C$5:$C$504,Expenses!$D$5:$D$504,$A72,Expenses!$A$5:$A$504,">="&F$67,Expenses!$A$5:$A$504,"<"&EDATE(F$67,1)) -> 0 | G72: =SUMIFS(Expenses!$C$5:$C$504,Expenses!$D$5:$D$504,$A72,Expenses!$A$5:$A$504,">="&G$67,Expenses!$A$5:$A$504,"<"&EDATE(G$67,1)) -> 0 | H72: =SUMIFS(Expenses!$C$5:$C$504,Expenses!$D$5:$D$504,$A72,Expenses!$A$5:$A$504,">="&H$67,Expenses!$A$5:$A$504,"<"&EDATE(H$67,1)) -> 0 | I72: =SUMIFS(Expenses!$C$5:$C$504,Expenses!$D$5:$D$504,$A72,Expenses!$A$5:$A$504,">="&I$67,Expenses!$A$5:$A$504,"<"&EDATE(I$67,1)) -> 0 | ... M72: =SUMIFS(Expenses!$C$5:$C$504,Expenses!$D$5:$D$504,$A72,Expenses!$A$5:$A$504,">="&M$67,Expenses!$A$5:$A$504,"<"&EDATE(M$67,1)) -> 0
A73: Insurance | B73: =SUMIFS(Expenses!$C$5:$C$504,Expenses!$D$5:$D$504,$A73,Expenses!$A$5:$A$504,">="&B$67,Expenses!$A$5:$A$504,"<"&EDATE(B$67,1)) -> 0 | C73: =SUMIFS(Expenses!$C$5:$C$504,Expenses!$D$5:$D$504,$A73,Expenses!$A$5:$A$504,">="&C$67,Expenses!$A$5:$A$504,"<"&EDATE(C$67,1)) -> 0 | D73: =SUMIFS(Expenses!$C$5:$C$504,Expenses!$D$5:$D$504,$A73,Expenses!$A$5:$A$504,">="&D$67,Expenses!$A$5:$A$504,"<"&EDATE(D$67,1)) -> 0 | E73: =SUMIFS(Expenses!$C$5:$C$504,Expenses!$D$5:$D$504,$A73,Expenses!$A$5:$A$504,">="&E$67,Expenses!$A$5:$A$504,"<"&EDATE(E$67,1)) -> 0 | F73: =SUMIFS(Expenses!$C$5:$C$504,Expenses!$D$5:$D$504,$A73,Expenses!$A$5:$A$504,">="&F$67,Expenses!$A$5:$A$504,"<"&EDATE(F$67,1)) -> 0 | G73: =SUMIFS(Expenses!$C$5:$C$504,Expenses!$D$5:$D$504,$A73,Expenses!$A$5:$A$504,">="&G$67,Expenses!$A$5:$A$504,"<"&EDATE(G$67,1)) -> 0 | H73: =SUMIFS(Expenses!$C$5:$C$504,Expenses!$D$5:$D$504,$A73,Expenses!$A$5:$A$504,">="&H$67,Expenses!$A$5:$A$504,"<"&EDATE(H$67,1)) -> 0 | I73: =SUMIFS(Expenses!$C$5:$C$504,Expenses!$D$5:$D$504,$A73,Expenses!$A$5:$A$504,">="&I$67,Expenses!$A$5:$A$504,"<"&EDATE(I$67,1)) -> 0 | ... M73: =SUMIFS(Expenses!$C$5:$C$504,Expenses!$D$5:$D$504,$A73,Expenses!$A$5:$A$504,">="&M$67,Expenses!$A$5:$A$504,"<"&EDATE(M$67,1)) -> 0
A74: Healthcare | B74: =SUMIFS(Expenses!$C$5:$C$504,Expenses!$D$5:$D$504,$A74,Expenses!$A$5:$A$504,">="&B$67,Expenses!$A$5:$A$504,"<"&EDATE(B$67,1)) -> 0 | C74: =SUMIFS(Expenses!$C$5:$C$504,Expenses!$D$5:$D$504,$A74,Expenses!$A$5:$A$504,">="&C$67,Expenses!$A$5:$A$504,"<"&EDATE(C$67,1)) -> 0 | D74: =SUMIFS(Expenses!$C$5:$C$504,Expenses!$D$5:$D$504,$A74,Expenses!$A$5:$A$504,">="&D$67,Expenses!$A$5:$A$504,"<"&EDATE(D$67,1)) -> 0 | E74: =SUMIFS(Expenses!$C$5:$C$504,Expenses!$D$5:$D$504,$A74,Expenses!$A$5:$A$504,">="&E$67,Expenses!$A$5:$A$504,"<"&EDATE(E$67,1)) -> 0 | F74: =SUMIFS(Expenses!$C$5:$C$504,Expenses!$D$5:$D$504,$A74,Expenses!$A$5:$A$504,">="&F$67,Expenses!$A$5:$A$504,"<"&EDATE(F$67,1)) -> 0 | G74: =SUMIFS(Expenses!$C$5:$C$504,Expenses!$D$5:$D$504,$A74,Expenses!$A$5:$A$504,">="&G$67,Expenses!$A$5:$A$504,"<"&EDATE(G$67,1)) -> 0 | H74: =SUMIFS(Expenses!$C$5:$C$504,Expenses!$D$5:$D$504,$A74,Expenses!$A$5:$A$504,">="&H$67,Expenses!$A$5:$A$504,"<"&EDATE(H$67,1)) -> 0 | I74: =SUMIFS(Expenses!$C$5:$C$504,Expenses!$D$5:$D$504,$A74,Expenses!$A$5:$A$504,">="&I$67,Expenses!$A$5:$A$504,"<"&EDATE(I$67,1)) -> 0 | ... M74: =SUMIFS(Expenses!$C$5:$C$504,Expenses!$D$5:$D$504,$A74,Expenses!$A$5:$A$504,">="&M$67,Expenses!$A$5:$A$504,"<"&EDATE(M$67,1)) -> 0
A75: Entertainment | B75: =SUMIFS(Expenses!$C$5:$C$504,Expenses!$D$5:$D$504,$A75,Expenses!$A$5:$A$504,">="&B$67,Expenses!$A$5:$A$504,"<"&EDATE(B$67,1)) -> 0 | C75: =SUMIFS(Expenses!$C$5:$C$504,Expenses!$D$5:$D$504,$A75,Expenses!$A$5:$A$504,">="&C$67,Expenses!$A$5:$A$504,"<"&EDATE(C$67,1)) -> 0 | D75: =SUMIFS(Expenses!$C$5:$C$504,Expenses!$D$5:$D$504,$A75,Expenses!$A$5:$A$504,">="&D$67,Expenses!$A$5:$A$504,"<"&EDATE(D$67,1)) -> 0 | E75: =SUMIFS(Expenses!$C$5:$C$504,Expenses!$D$5:$D$504,$A75,Expenses!$A$5:$A$504,">="&E$67,Expenses!$A$5:$A$504,"<"&EDATE(E$67,1)) -> 0 | F75: =SUMIFS(Expenses!$C$5:$C$504,Expenses!$D$5:$D$504,$A75,Expenses!$A$5:$A$504,">="&F$67,Expenses!$A$5:$A$504,"<"&EDATE(F$67,1)) -> 0 | G75: =SUMIFS(Expenses!$C$5:$C$504,Expenses!$D$5:$D$504,$A75,Expenses!$A$5:$A$504,">="&G$67,Expenses!$A$5:$A$504,"<"&EDATE(G$67,1)) -> 0 | H75: =SUMIFS(Expenses!$C$5:$C$504,Expenses!$D$5:$D$504,$A75,Expenses!$A$5:$A$504,">="&H$67,Expenses!$A$5:$A$504,"<"&EDATE(H$67,1)) -> 0 | I75: =SUMIFS(Expenses!$C$5:$C$504,Expenses!$D$5:$D$504,$A75,Expenses!$A$5:$A$504,">="&I$67,Expenses!$A$5:$A$504,"<"&EDATE(I$67,1)) -> 0 | ... M75: =SUMIFS(Expenses!$C$5:$C$504,Expenses!$D$5:$D$504,$A75,Expenses!$A$5:$A$504,">="&M$67,Expenses!$A$5:$A$504,"<"&EDATE(M$67,1)) -> 0
A76: Subscriptions | B76: =SUMIFS(Expenses!$C$5:$C$504,Expenses!$D$5:$D$504,$A76,Expenses!$A$5:$A$504,">="&B$67,Expenses!$A$5:$A$504,"<"&EDATE(B$67,1)) -> 0 | C76: =SUMIFS(Expenses!$C$5:$C$504,Expenses!$D$5:$D$504,$A76,Expenses!$A$5:$A$504,">="&C$67,Expenses!$A$5:$A$504,"<"&EDATE(C$67,1)) -> 0 | D76: =SUMIFS(Expenses!$C$5:$C$504,Expenses!$D$5:$D$504,$A76,Expenses!$A$5:$A$504,">="&D$67,Expenses!$A$5:$A$504,"<"&EDATE(D$67,1)) -> 0 | E76: =SUMIFS(Expenses!$C$5:$C$504,Expenses!$D$5:$D$504,$A76,Expenses!$A$5:$A$504,">="&E$67,Expenses!$A$5:$A$504,"<"&EDATE(E$67,1)) -> 0 | F76: =SUMIFS(Expenses!$C$5:$C$504,Expenses!$D$5:$D$504,$A76,Expenses!$A$5:$A$504,">="&F$67,Expenses!$A$5:$A$504,"<"&EDATE(F$67,1)) -> 0 | G76: =SUMIFS(Expenses!$C$5:$C$504,Expenses!$D$5:$D$504,$A76,Expenses!$A$5:$A$504,">="&G$67,Expenses!$A$5:$A$504,"<"&EDATE(G$67,1)) -> 0 | H76: =SUMIFS(Expenses!$C$5:$C$504,Expenses!$D$5:$D$504,$A76,Expenses!$A$5:$A$504,">="&H$67,Expenses!$A$5:$A$504,"<"&EDATE(H$67,1)) -> 0 | I76: =SUMIFS(Expenses!$C$5:$C$504,Expenses!$D$5:$D$504,$A76,Expenses!$A$5:$A$504,">="&I$67,Expenses!$A$5:$A$504,"<"&EDATE(I$67,1)) -> 0 | ... M76: =SUMIFS(Expenses!$C$5:$C$504,Expenses!$D$5:$D$504,$A76,Expenses!$A$5:$A$504,">="&M$67,Expenses!$A$5:$A$504,"<"&EDATE(M$67,1)) -> 0
A77: Shopping | B77: =SUMIFS(Expenses!$C$5:$C$504,Expenses!$D$5:$D$504,$A77,Expenses!$A$5:$A$504,">="&B$67,Expenses!$A$5:$A$504,"<"&EDATE(B$67,1)) -> 0 | C77: =SUMIFS(Expenses!$C$5:$C$504,Expenses!$D$5:$D$504,$A77,Expenses!$A$5:$A$504,">="&C$67,Expenses!$A$5:$A$504,"<"&EDATE(C$67,1)) -> 0 | D77: =SUMIFS(Expenses!$C$5:$C$504,Expenses!$D$5:$D$504,$A77,Expenses!$A$5:$A$504,">="&D$67,Expenses!$A$5:$A$504,"<"&EDATE(D$67,1)) -> 0 | E77: =SUMIFS(Expenses!$C$5:$C$504,Expenses!$D$5:$D$504,$A77,Expenses!$A$5:$A$504,">="&E$67,Expenses!$A$5:$A$504,"<"&EDATE(E$67,1)) -> 0 | F77: =SUMIFS(Expenses!$C$5:$C$504,Expenses!$D$5:$D$504,$A77,Expenses!$A$5:$A$504,">="&F$67,Expenses!$A$5:$A$504,"<"&EDATE(F$67,1)) -> 0 | G77: =SUMIFS(Expenses!$C$5:$C$504,Expenses!$D$5:$D$504,$A77,Expenses!$A$5:$A$504,">="&G$67,Expenses!$A$5:$A$504,"<"&EDATE(G$67,1)) -> 0 | H77: =SUMIFS(Expenses!$C$5:$C$504,Expenses!$D$5:$D$504,$A77,Expenses!$A$5:$A$504,">="&H$67,Expenses!$A$5:$A$504,"<"&EDATE(H$67,1)) -> 0 | I77: =SUMIFS(Expenses!$C$5:$C$504,Expenses!$D$5:$D$504,$A77,Expenses!$A$5:$A$504,">="&I$67,Expenses!$A$5:$A$504,"<"&EDATE(I$67,1)) -> 0 | ... M77: =SUMIFS(Expenses!$C$5:$C$504,Expenses!$D$5:$D$504,$A77,Expenses!$A$5:$A$504,">="&M$67,Expenses!$A$5:$A$504,"<"&EDATE(M$67,1)) -> 0
A78: Debt | B78: =SUMIFS(Expenses!$C$5:$C$504,Expenses!$D$5:$D$504,$A78,Expenses!$A$5:$A$504,">="&B$67,Expenses!$A$5:$A$504,"<"&EDATE(B$67,1)) -> 0 | C78: =SUMIFS(Expenses!$C$5:$C$504,Expenses!$D$5:$D$504,$A78,Expenses!$A$5:$A$504,">="&C$67,Expenses!$A$5:$A$504,"<"&EDATE(C$67,1)) -> 0 | D78: =SUMIFS(Expenses!$C$5:$C$504,Expenses!$D$5:$D$504,$A78,Expenses!$A$5:$A$504,">="&D$67,Expenses!$A$5:$A$504,"<"&EDATE(D$67,1)) -> 0 | E78: =SUMIFS(Expenses!$C$5:$C$504,Expenses!$D$5:$D$504,$A78,Expenses!$A$5:$A$504,">="&E$67,Expenses!$A$5:$A$504,"<"&EDATE(E$67,1)) -> 0 | F78: =SUMIFS(Expenses!$C$5:$C$504,Expenses!$D$5:$D$504,$A78,Expenses!$A$5:$A$504,">="&F$67,Expenses!$A$5:$A$504,"<"&EDATE(F$67,1)) -> 0 | G78: =SUMIFS(Expenses!$C$5:$C$504,Expenses!$D$5:$D$504,$A78,Expenses!$A$5:$A$504,">="&G$67,Expenses!$A$5:$A$504,"<"&EDATE(G$67,1)) -> 0 | H78: =SUMIFS(Expenses!$C$5:$C$504,Expenses!$D$5:$D$504,$A78,Expenses!$A$5:$A$504,">="&H$67,Expenses!$A$5:$A$504,"<"&EDATE(H$67,1)) -> 0 | I78: =SUMIFS(Expenses!$C$5:$C$504,Expenses!$D$5:$D$504,$A78,Expenses!$A$5:$A$504,">="&I$67,Expenses!$A$5:$A$504,"<"&EDATE(I$67,1)) -> 0 | ... M78: =SUMIFS(Expenses!$C$5:$C$504,Expenses!$D$5:$D$504,$A78,Expenses!$A$5:$A$504,">="&M$67,Expenses!$A$5:$A$504,"<"&EDATE(M$67,1)) -> 0
A79: Other | B79: =SUMIFS(Expenses!$C$5:$C$504,Expenses!$D$5:$D$504,$A79,Expenses!$A$5:$A$504,">="&B$67,Expenses!$A$5:$A$504,"<"&EDATE(B$67,1)) -> 0 | C79: =SUMIFS(Expenses!$C$5:$C$504,Expenses!$D$5:$D$504,$A79,Expenses!$A$5:$A$504,">="&C$67,Expenses!$A$5:$A$504,"<"&EDATE(C$67,1)) -> 0 | D79: =SUMIFS(Expenses!$C$5:$C$504,Expenses!$D$5:$D$504,$A79,Expenses!$A$5:$A$504,">="&D$67,Expenses!$A$5:$A$504,"<"&EDATE(D$67,1)) -> 0 | E79: =SUMIFS(Expenses!$C$5:$C$504,Expenses!$D$5:$D$504,$A79,Expenses!$A$5:$A$504,">="&E$67,Expenses!$A$5:$A$504,"<"&EDATE(E$67,1)) -> 0 | F79: =SUMIFS(Expenses!$C$5:$C$504,Expenses!$D$5:$D$504,$A79,Expenses!$A$5:$A$504,">="&F$67,Expenses!$A$5:$A$504,"<"&EDATE(F$67,1)) -> 0 | G79: =SUMIFS(Expenses!$C$5:$C$504,Expenses!$D$5:$D$504,$A79,Expenses!$A$5:$A$504,">="&G$67,Expenses!$A$5:$A$504,"<"&EDATE(G$67,1)) -> 0 | H79: =SUMIFS(Expenses!$C$5:$C$504,Expenses!$D$5:$D$504,$A79,Expenses!$A$5:$A$504,">="&H$67,Expenses!$A$5:$A$504,"<"&EDATE(H$67,1)) -> 0 | I79: =SUMIFS(Expenses!$C$5:$C$504,Expenses!$D$5:$D$504,$A79,Expenses!$A$5:$A$504,">="&I$67,Expenses!$A$5:$A$504,"<"&EDATE(I$67,1)) -> 0 | ... M79: =SUMIFS(Expenses!$C$5:$C$504,Expenses!$D$5:$D$504,$A79,Expenses!$A$5:$A$504,">="&M$67,Expenses!$A$5:$A$504,"<"&EDATE(M$67,1)) -> 0
A80: Total Spending | B80: =SUM(B68:B79) -> 85.32 | C80: =SUM(C68:C79) -> 0 | D80: =SUM(D68:D79) -> 0 | E80: =SUM(E68:E79) -> 0 | F80: =SUM(F68:F79) -> 0 | G80: =SUM(G68:G79) -> 0 | H80: =SUM(H68:H79) -> 0 | I80: =SUM(I68:I79) -> 0 | ... M80: =SUM(M68:M79) -> 0
A83: Monthly Income by Type ($)
...

Sheet Investments
A1: Investment Account Tracker | I1: Legend
A2: Enter your account balance once a month, plus any money you added or withdrew. Gain $/% is calculated automatically and excludes your own contributions. | I2: Blue text = your input
I3: Black text = formula (don't edit)
A4: Starting Balances (as of Dec 31, 2025)
A5: Account | B5: Balance ($)
A6: HSA (UP) | B6: 1000
A7: HSA (Valstone) | B7: 0
A8: Roth IRA | B8: 0
A9: 401k (UP) | B9: 0
A10: 401k (Valstone) | B10: 0
A11: HYSA | B11: 0
A12: Checking - US | B12: 0
A13: Checking - FB | B13: 0
A16: Date | B16: Account | C16: Balance ($) | D16: Contribution / Withdrawal ($) | E16: Prior Balance ($) | F16: Gain ($) | G16: Gain (%)
A17: 46023 | B17: HSA (UP) | C17: 1050 | D17: 50 | E17: =IFERROR(INDEX($B$6:$B$13,MATCH(B17,$A$6:$A$13,0)),"") -> 1000 | F17: =IF(OR(C17="",E17=""),"",C17-E17-D17) -> 0 | G17: =IFERROR(F17/E17,"") -> 0
A18: 46023 | B18: HSA (Valstone) | D18: 0 | E18: =IFERROR(INDEX($B$6:$B$13,MATCH(B18,$A$6:$A$13,0)),"") -> 0 | F18: =IF(OR(C18="",E18=""),"",C18-E18-D18) | G18: =IFERROR(F18/E18,"")
A19: 46023 | B19: Roth IRA | D19: 0 | E19: =IFERROR(INDEX($B$6:$B$13,MATCH(B19,$A$6:$A$13,0)),"") -> 0 | F19: =IF(OR(C19="",E19=""),"",C19-E19-D19) | G19: =IFERROR(F19/E19,"")
A20: 46023 | B20: 401k (UP) | D20: 0 | E20: =IFERROR(INDEX($B$6:$B$13,MATCH(B20,$A$6:$A$13,0)),"") -> 0 | F20: =IF(OR(C20="",E20=""),"",C20-E20-D20) | G20: =IFERROR(F20/E20,"")
A21: 46023 | B21: 401k (Valstone) | D21: 0 | E21: =IFERROR(INDEX($B$6:$B$13,MATCH(B21,$A$6:$A$13,0)),"") -> 0 | F21: =IF(OR(C21="",E21=""),"",C21-E21-D21) | G21: =IFERROR(F21/E21,"")
A22: 46023 | B22: HYSA | D22: 0 | E22: =IFERROR(INDEX($B$6:$B$13,MATCH(B22,$A$6:$A$13,0)),"") -> 0 | F22: =IF(OR(C22="",E22=""),"",C22-E22-D22) | G22: =IFERROR(F22/E22,"")
A23: 46023 | B23: Checking (USB) | D23: 0 | E23: =IFERROR(INDEX($B$6:$B$13,MATCH(B23,$A$6:$A$13,0)),"") | F23: =IF(OR(C23="",E23=""),"",C23-E23-D23) | G23: =IFERROR(F23/E23,"")
A24: 46023 | B24: Checking (FIB) | D24: 0 | E24: =IFERROR(INDEX($B$6:$B$13,MATCH(B24,$A$6:$A$13,0)),"") | F24: =IF(OR(C24="",E24=""),"",C24-E24-D24) | G24: =IFERROR(F24/E24,"")
A25: 46054 | B25: HSA (UP) | D25: 0 | E25: =C17 -> 1050 | F25: =IF(OR(C25="",E25=""),"",C25-E25-D25) | G25: =IFERROR(F25/E25,"") -> 0
A26: 46054 | B26: HSA (Valstone) | D26: 0 | E26: =C18 | F26: =IF(OR(C26="",E26=""),"",C26-E26-D26) | G26: =IFERROR(F26/E26,"")
A27: 46054 | B27: Roth IRA | D27: 0 | E27: =C19 | F27: =IF(OR(C27="",E27=""),"",C27-E27-D27) | G27: =IFERROR(F27/E27,"")
A28: 46054 | B28: 401k (UP) | D28: 0 | E28: =C20 | F28: =IF(OR(C28="",E28=""),"",C28-E28-D28) | G28: =IFERROR(F28/E28,"")
A29: 46054 | B29: 401k (Valstone) | D29: 0 | E29: =C21 | F29: =IF(OR(C29="",E29=""),"",C29-E29-D29) | G29: =IFERROR(F29/E29,"")
A30: 46054 | B30: HYSA | D30: 0 | E30: =C22 | F30: =IF(OR(C30="",E30=""),"",C30-E30-D30) | G30: =IFERROR(F30/E30,"")
A31: 46054 | B31: Checking (USB) | D31: 0 | E31: =C23 | F31: =IF(OR(C31="",E31=""),"",C31-E31-D31) | G31: =IFERROR(F31/E31,"")
A32: 46054 | B32: Checking (FIB) | D32: 0 | E32: =C24 | F32: =IF(OR(C32="",E32=""),"",C32-E32-D32) | G32: =IFERROR(F32/E32,"")
A33: 46082 | B33: HSA (UP) | D33: 0 | E33: =C25 | F33: =IF(OR(C33="",E33=""),"",C33-E33-D33) | G33: =IFERROR(F33/E33,"")
A34: 46082 | B34: HSA (Valstone) | D34: 0 | E34: =C26 | F34: =IF(OR(C34="",E34=""),"",C34-E34-D34) | G34: =IFERROR(F34/E34,"")
A35: 46082 | B35: Roth IRA | D35: 0 | E35: =C27 | F35: =IF(OR(C35="",E35=""),"",C35-E35-D35) | G35: =IFERROR(F35/E35,"")
A36: 46082 | B36: 401k (UP) | D36: 0 | E36: =C28 | F36: =IF(OR(C36="",E36=""),"",C36-E36-D36) | G36: =IFERROR(F36/E36,"")
... A112: 46357 | B112: Checking (FIB) | D112: 0 | E112: =C104 | F112: =IF(OR(C112="",E112=""),"",C112-E112-D112) | G112: =IFERROR(F112/E112,"")

Sheet Expenses
A1: Expenses
A2: Log every expense as it happens. Date, Description, Amount are yours to fill in; pick a Type from the dropdown.
A4: Date | B4: Description | C4: Amount ($) | D4: Type
A5: 46027 | B5: Example: Trader Joe's | C5: 85.32 | D5: Groceries

Sheet Income
A1: Income
A2: Log each paycheck, dividend, or other income event. Date, Description, Amount are yours to fill in; pick a Type from the dropdown.
A4: Date | B4: Description | C4: Amount ($) | D4: Type
A5: 46037 | B5: Example: Paycheck | C5: 3200 | D5: W2

Sheet Lists
A1: Account Names | B1: Expense Categories | C1: Income Types
A2: HSA (UP) | B2: Groceries | C2: Salary
A3: HSA (Valstone) | B3: Housing | C3: Dividends
A4: Roth IRA | B4: Vehicle | C4: Interest
A5: 401k (UP) | B5: Utilities | C5: Bonus
A6: 401k (Valstone) | B6: Insurance | C6: Other
A7: HYSA | B7: Entertainment
A8: Checking (USB) | B8: Debt (Tim School)
A9: Checking (FIB) | B9: Debt (Cheyney School)
B10: Other
